[2025-01-29T02:37:08.998+0000] {taskinstance.py:1956} INFO - Dependencies all met for dep_context=non-requeueable deps ti=<TaskInstance: monitoring_dag.run_drift_monitoring scheduled__2025-01-28T00:00:00+00:00 [queued]>
[2025-01-29T02:37:09.009+0000] {taskinstance.py:1956} INFO - Dependencies all met for dep_context=requeueable deps ti=<TaskInstance: monitoring_dag.run_drift_monitoring scheduled__2025-01-28T00:00:00+00:00 [queued]>
[2025-01-29T02:37:09.010+0000] {taskinstance.py:2170} INFO - Starting attempt 1 of 2
[2025-01-29T02:37:09.027+0000] {taskinstance.py:2191} INFO - Executing <Task(PythonOperator): run_drift_monitoring> on 2025-01-28 00:00:00+00:00
[2025-01-29T02:37:09.034+0000] {standard_task_runner.py:60} INFO - Started process 1636 to run task
[2025-01-29T02:37:09.061+0000] {standard_task_runner.py:87} INFO - Running: ['***', 'tasks', 'run', 'monitoring_dag', 'run_drift_monitoring', 'scheduled__2025-01-28T00:00:00+00:00', '--job-id', '9', '--raw', '--subdir', 'DAGS_FOLDER/monitoring_dag.py', '--cfg-path', '/tmp/tmp3d3ksxqw']
[2025-01-29T02:37:09.068+0000] {standard_task_runner.py:88} INFO - Job 9: Subtask run_drift_monitoring
[2025-01-29T02:37:09.140+0000] {warnings.py:109} WARNING - /home/***/.local/lib/python3.8/site-packages/***/settings.py:194: DeprecationWarning: The sql_alchemy_conn option in [core] has been moved to the sql_alchemy_conn option in [database] - the old setting has been used, but please update your config.
  SQL_ALCHEMY_CONN = conf.get("database", "SQL_ALCHEMY_CONN")

[2025-01-29T02:37:09.187+0000] {task_command.py:423} INFO - Running <TaskInstance: monitoring_dag.run_drift_monitoring scheduled__2025-01-28T00:00:00+00:00 [running]> on host 3a379e002bc3
[2025-01-29T02:37:09.275+0000] {taskinstance.py:2480} INFO - Exporting env vars: AIRFLOW_CTX_DAG_OWNER='***' AIRFLOW_CTX_DAG_ID='monitoring_dag' AIRFLOW_CTX_TASK_ID='run_drift_monitoring' AIRFLOW_CTX_EXECUTION_DATE='2025-01-28T00:00:00+00:00' AIRFLOW_CTX_TRY_NUMBER='1' AIRFLOW_CTX_DAG_RUN_ID='scheduled__2025-01-28T00:00:00+00:00'
[2025-01-29T02:37:09.317+0000] {taskinstance.py:2698} ERROR - Task failed with exception
Traceback (most recent call last):
  File "/home/airflow/.local/lib/python3.8/site-packages/airflow/models/taskinstance.py", line 433, in _execute_task
    result = execute_callable(context=context, **execute_callable_kwargs)
  File "/home/airflow/.local/lib/python3.8/site-packages/airflow/operators/python.py", line 199, in execute
    return_value = self.execute_callable()
  File "/home/airflow/.local/lib/python3.8/site-packages/airflow/operators/python.py", line 216, in execute_callable
    return self.python_callable(*self.op_args, **self.op_kwargs)
  File "/opt/airflow/dags/monitoring_dag.py", line 12, in run_drift_monitoring
    subprocess.run(["python", SCRIPT_PATH], check=True)
  File "/usr/local/lib/python3.8/subprocess.py", line 516, in run
    raise CalledProcessError(retcode, process.args,
subprocess.CalledProcessError: Command '['python', '/opt/airflow/dags/monitoring/drift_monitoring.py']' returned non-zero exit status 2.
[2025-01-29T02:37:09.332+0000] {taskinstance.py:1138} INFO - Marking task as UP_FOR_RETRY. dag_id=monitoring_dag, task_id=run_drift_monitoring, execution_date=20250128T000000, start_date=20250129T023709, end_date=20250129T023709
[2025-01-29T02:37:09.346+0000] {standard_task_runner.py:107} ERROR - Failed to execute job 9 for task run_drift_monitoring (Command '['python', '/opt/airflow/dags/monitoring/drift_monitoring.py']' returned non-zero exit status 2.; 1636)
[2025-01-29T02:37:09.386+0000] {local_task_job_runner.py:234} INFO - Task exited with return code 1
[2025-01-29T02:37:09.403+0000] {taskinstance.py:3280} INFO - 0 downstream tasks scheduled from follow-on schedule check
